============================= test session starts ==============================
platform linux -- Python 3.12.3, pytest-8.4.1, pluggy-1.6.0 -- /root/sanctum-letta-mcp/venv/bin/python3
cachedir: .pytest_cache
rootdir: /root/sanctum-letta-mcp
configfile: pytest.ini
testpaths: tests
plugins: asyncio-1.1.0, socket-0.7.0, timeout-2.4.0, anyio-4.10.0, cov-6.2.1, mock-3.12.0
asyncio: mode=Mode.AUTO, asyncio_default_fixture_loop_scope=None, asyncio_default_test_loop_scope=function
timeout: 60.0s
timeout method: thread
timeout func_only: False
collecting ... collected 61 items / 1 error

==================================== ERRORS ====================================
________________ ERROR collecting tests/unit/test_mcp_server.py ________________
ImportError while importing test module '/root/sanctum-letta-mcp/tests/unit/test_mcp_server.py'.
Hint: make sure your test modules/packages have valid Python names.
Traceback:
/usr/lib/python3.12/importlib/__init__.py:90: in import_module
    return _bootstrap._gcd_import(name[level:], package, level)
           ^^^^^^^^^^^^^^^^^^^^^^^^^^^^^^^^^^^^^^^^^^^^^^^^^^^^
tests/unit/test_mcp_server.py:3: in <module>
    from promptyoself_mcp_server import health, serve_stdio_transport, serve_http_transport, serve_sse_transport
E   ImportError: cannot import name 'serve_stdio_transport' from 'promptyoself_mcp_server' (/root/sanctum-letta-mcp/promptyoself_mcp_server.py)
=========================== short test summary info ============================
ERROR tests/unit/test_mcp_server.py
!!!!!!!!!!!!!!!!!!!! Interrupted: 1 error during collection !!!!!!!!!!!!!!!!!!!!
========================= 1 warning, 1 error in 0.80s ==========================
